Workbook

Sheet Salary
A1: YEAR | B1: MONTH | C1: INCOME | P1: DEDUCTIONS | S1: Employer PF Share | T1: Pension Share | U1: Net Income
C2: BASIC | D2: HRA | E2: MCA | F2: Bonus | G2: CEA | H2: Other Allowance | I2: Shift/Oncall | J2: Leave Encash | K2: Other Earning | L2: Special Allowance | M2: Internet Allowance | N2: Reimbursement | O2: Gross Income | P2: Employee PF Share | Q2: Prof Tax | R2: Income Tax
A3: 2022 | B3: JUL | O3: 8667 | U3: 8667
A4: 2022 | B4: AUG | O4: 20000 | U4: 20000
A5: 2022 | B5: SEP | O5: 20000 | U5: 20000
A6: 2022 | B6: DEC | O6: 20000 | U6: 20000
A7: 2023 | B7: JAN | O7: 20000 | U7: 20000
A8: 2023 | B8: FEB | O8: 20000 | U8: 20000
A9: 2023 | B9: MAR | O9: 20000 | U9: 20000
A10: 2023 | B10: APR | O10: 5162 | U10: 5162
A11: 2023 | B11: MAY | O11: 14667 | U11: 14667
A12: 2023 | B12: JUN | O12: 20000 | U12: 20000
A13: 2023 | B13: JUL | O13: 21871 | U13: 21871
A14: 2023 | B14: AUG | C14: 16802 | D14: 6721 | E14: 2688 | F14: 1399 | G14: 645 | H14: 3331 | I14: 700 | O14: =SUM(C14:N14) -> 32286 | P14: 1800 | Q14: 200 | S14: 766 | T14: 1250 | U14: =O14-SUM(P14:R14) -> 30286
A15: 2023 | B15: SEP | C15: 20834 | D15: 8334 | E15: 3333 | F15: 1735 | G15: 800 | H15: 4131 | I15: 4550 | O15: =SUM(C15:N15) -> 43717 | P15: 1800 | Q15: 200 | S15: 1250 | T15: 1250 | U15: =O15-SUM(P15:R15) -> 41717
A16: 2023 | B16: OCT | C16: 20834 | D16: 8334 | E16: 3333 | F16: 1735 | G16: 800 | H16: 4131 | I16: 4550 | O16: =SUM(C16:N16) -> 43717 | P16: 1800 | Q16: 200 | S16: 1250 | T16: 1250 | U16: =O16-SUM(P16:R16) -> 41717
A17: 2023 | B17: NOV | C17: 20834 | D17: 8334 | E17: 3333 | F17: 1735 | G17: 800 | H17: 4131 | I17: 4900 | O17: =SUM(C17:N17) -> 44067 | P17: 1800 | Q17: 200 | S17: 1250 | T17: 1250 | U17: =O17-SUM(P17:R17) -> 42067
A18: 2023 | B18: DEC | C18: 20834 | D18: 8334 | E18: 3333 | F18: 1735 | G18: 800 | H18: 4131 | I18: 3500 | J18: 4109 | O18: =SUM(C18:N18) -> 46776 | P18: 1800 | Q18: 200 | S18: 1250 | T18: 1250 | U18: =O18-SUM(P18:R18) -> 44776
A19: 2024 | B19: JAN | C19: 20834 | D19: 8334 | E19: 3333 | F19: 1735 | G19: 800 | H19: 4131 | I19: 4900 | O19: =SUM(C19:N19) -> 44067 | P19: 1800 | Q19: 200 | S19: 1250 | T19: 1250 | U19: =O19-SUM(P19:R19) -> 42067
A20: 2024 | B20: FEB | C20: 20834 | D20: 8334 | E20: 3333 | F20: 1735 | G20: 800 | H20: 4131 | I20: 9100 | O20: =SUM(C20:N20) -> 48267 | P20: 1800 | Q20: 200 | S20: 2500 | U20: =O20-SUM(P20:R20) -> 46267
A21: 2024 | B21: MAR | C21: 20834 | D21: 8334 | E21: 3333 | F21: 1735 | G21: 800 | H21: 4131 | I21: 4550 | O21: =SUM(C21:N21) -> 43717 | P21: 1800 | Q21: 200 | S21: 2500 | U21: =O21-SUM(P21:R21) -> 41717
A22: 2024 | B22: APR | C22: 22084 | D22: 8834 | E22: 3333 | G22: 800 | H22: 6466 | I22: 4850 | O22: =SUM(C22:N22) -> 46367 | P22: 1800 | Q22: 200 | S22: 2650 | U22: =O22-SUM(P22:R22) -> 44367
A23: 2024 | B23: MAY | C23: 22084 | D23: 8834 | E23: 3333 | G23: 800 | H23: 6466 | I23: 4600 | O23: =SUM(C23:N23) -> 46117 | P23: 1800 | Q23: 200 | S23: 2650 | U23: =O23-SUM(P23:R23) -> 44117
A24: 2024 | B24: JUN | C24: 22084 | D24: 8834 | E24: 3333 | G24: 800 | H24: 6466 | I24: 2700 | O24: =SUM(C24:N24) -> 44217 | P24: 1800 | Q24: 200 | S24: 2650 | U24: =O24-SUM(P24:R24) -> 42217
A25: 2024 | B25: JUL | C25: 22084 | D25: 8834 | E25: 3333 | G25: 800 | H25: 6466 | I25: 3850 | O25: =SUM(C25:N25) -> 45367 | P25: 1800 | Q25: 200 | S25: 2650 | U25: =O25-SUM(P25:R25) -> 43367
A26: 2024 | B26: AUG | C26: 22084 | D26: 8834 | E26: 3333 | G26: 800 | H26: 6466 | I26: 3450 | O26: =SUM(C26:N26) -> 44967 | P26: 1800 | Q26: 200 | S26: 2650 | U26: =O26-SUM(P26:R26) -> 42967
A27: 2024 | B27: SEP | C27: 22084 | D27: 8834 | E27: 3333 | G27: 800 | H27: 6466 | I27: 5250 | O27: =SUM(C27:N27) -> 46767 | P27: 1800 | Q27: 200 | S27: 2650 | U27: =O27-SUM(P27:R27) -> 44767
A28: 2024 | B28: OCT | C28: 22084 | D28: 8834 | E28: 3333 | G28: 800 | H28: 6466 | I28: 3150 | O28: =SUM(C28:N28) -> 44667 | P28: 1800 | Q28: 200 | S28: 2650 | U28: =O28-SUM(P28:R28) -> 42667
A29: 2024 | B29: NOV | C29: 22084 | D29: 8834 | E29: 3333 | G29: 800 | H29: 6466 | I29: 7350 | O29: =SUM(C29:N29) -> 48867 | P29: 1800 | Q29: 200 | S29: 2650 | U29: =O29-SUM(P29:R29) -> 46867
A30: 2024 | B30: DEC | C30: 22084 | D30: 8834 | E30: 3333 | G30: 800 | H30: 6466 | I30: 6250 | J30: 10890.41 | O30: =SUM(C30:N30) -> 58657.41 | P30: 1800 | Q30: 200 | S30: 2650 | U30: =O30-SUM(P30:R30) -> 56657.41
A31: 2025 | B31: JAN | C31: 22084 | D31: 8834 | E31: 3333 | G31: 800 | H31: 6466 | I31: 7950 | O31: =SUM(C31:N31) -> 49467 | P31: 1800 | Q31: 200 | S31: 2650 | U31: =O31-SUM(P31:R31) -> 47467
A32: 2025 | B32: FEB | C32: 22084 | D32: 8834 | E32: 3333 | G32: 800 | H32: 6466 | I32: 12900 | O32: =SUM(C32:N32) -> 54417 | P32: 1800 | Q32: 200 | S32: 2650 | U32: =O32-SUM(P32:R32) -> 52417
A33: 2025 | B33: MAR | C33: 23629 | D33: 9452 | E33: 3333 | G33: 800 | H33: 7209 | I33: 4500 | K33: 6183.33 | O33: =SUM(C33:N33) -> 55106.33 | P33: 1800 | Q33: 200 | S33: 2835 | U33: =O33-SUM(P33:R33) -> 53106.33
A34: 2025 | B34: APR | C34: 23629 | D34: 9452 | E34: 3333 | G34: 800 | H34: 7209 | I34: 9450 | O34: =SUM(C34:N34) -> 53873 | P34: 1800 | Q34: 200 | S34: 2835 | U34: =O34-SUM(P34:R34) -> 51873
A35: 2025 | B35: MAY | C35: 23629 | D35: 9452 | E35: 3333 | G35: 800 | H35: 7209 | I35: 9900 | O35: =SUM(C35:N35) -> 54323 | P35: 1800 | Q35: 200 | S35: 2835 | U35: =O35-SUM(P35:R35) -> 52323
A36: 2025 | B36: JUN | C36: 23629 | D36: 9452 | E36: 3333 | G36: 800 | H36: 7209 | I36: 7950 | O36: =SUM(C36:N36) -> 52373 | P36: 1800 | Q36: 200 | S36: 2835 | U36: =O36-SUM(P36:R36) -> 50373
A37: 2025 | B37: JUL | C37: 23629 | D37: 9452 | E37: 3333 | G37: 800 | H37: 7209 | I37: 8550 | O37: =SUM(C37:N37) -> 52973 | P37: 1800 | Q37: 200 | S37: 2835 | U37: =O37-SUM(P37:R37) -> 50973
A38: 2025 | B38: AUG | C38: 23629 | D38: 9452 | E38: 3333 | G38: 800 | H38: 7209 | I38: 12600 | O38: =SUM(C38:N38) -> 57023 | P38: 1800 | Q38: 200 | S38: 2835 | U38: =O38-SUM(P38:R38) -> 55023
A39: 2025 | B39: SEP | C39: 23629 | D39: 9452 | E39: 3333 | G39: 800 | H39: 7209 | I39: 8850 | O39: =SUM(C39:N39) -> 53273 | P39: 1800 | Q39: 200 | S39: 1586 | T39: 1250 | U39: =O39-SUM(P39:R39) -> 51273
A40: 2025 | B40: OCT | C40: 23629 | D40: 9452 | E40: 3333 | G40: 800 | H40: 7209 | I40: 7950 | O40: =SUM(C40:N40) -> 52373 | P40: 1800 | Q40: 200 | S40: 1586 | T40: 1250 | U40: =O40-SUM(P40:R40) -> 50373
...

Sheet Calculations
A1: YEAR | B1: Net Income | C1: Employee PF | D1: Employer PF | E1: PF Total | F1: Yearly Total | H1: Employer | I1: Employment-Type | J1: Net Income | K1: PF (Employee + Employer) | L1: Net Income+ PF | M1: Professional Tax | N1: Income Tax | O1: Pension | P1: Over All Gross (TakeHome + PF + Tax + Pension) | R1: Assessment Year | S1: Financial Year | T1: Tax Year | U1: Overall Amount
A2: 2023 | B2: =SUM(Salary!U14:U18) -> 200563 | C2: =SUM(Salary!P14:P18) -> 9000 | D2: =SUM(Salary!S14:S18) -> 5766 | E2: =SUM(C2,D2) -> 14766 | F2: =SUM(B2,E2) -> 215329 | H2: Volante | I2: Internship | P2: =SUM(Salary!U3:U13) -> 190367 | R2: 2024-2025 | S2: Apr 2023 - Mar 2024 | T2: 2023-2024 | U2: =SUM(Salary!O14:O21)+SUM(Salary!S14:S21)+SUM(Salary!T14:T21) -> 366130
A3: 2024 | B3: =SUM(Salary!U19:U30) -> 538044.41 | C3: =SUM(Salary!P19:P30) -> 21600 | D3: =SUM(Salary!S19:S30) -> 30100 | E3: =SUM(C3,D3) -> 51700 | F3: =SUM(B3,E3) -> 589744.41 | H3: Volante | I3: Full Time | J3: =SUM(Salary!U14:U42) -> 1364319.1 | K3: =SUM(Salary!P14:P42, Salary!S14:S42) -> 116626 | L3: =SUM(J3,K3) -> 1480945.1 | M3: =SUM(Salary!Q14:Q42) -> 5800 | N3: 0 | O3: =SUM(Salary!T12:T42) -> 12500 | P3: =SUM(L3,O3) -> 1493445.1 | R3: 2025-2026 | S3: Apr 2024 - Mar 2025 | T3: 2024-2025 | U3: =SUM(Salary!O22:O33)+SUM(Salary!S22:S33)+SUM(Salary!T22:T33) -> 616968.74
A4: 2025 | B4: =SUM(Salary!U31:U42) -> 625711.67 | C4: =SUM(Salary!P31:P42) -> 21600 | D4: =SUM(Salary!S31:S42) -> 28560 | E4: =SUM(C4,D4) -> 50160 | F4: =SUM(B4,E4) -> 675871.67 | H4: Factset | I4: Full Time | J4: =SUM(Salary!U43:U47) -> 419244 | K4: =SUM(Salary!P43:P47, Salary!S43:S47) -> 27397 | L4: =SUM(J4,K4) -> 446641 | M4: =SUM(Salary!Q43:Q47) -> 1000 | N4: 0 | O4: =SUM(Salary!T43:T47) -> 5241 | P4: =SUM(L4,O4) -> 451882 | R4: 2026-2027 | S4: Apr 2025 - Mar 2026 | T4: 2025-2026 | U4: =SUM(Salary!O34:O45) -> 763482.34
A5: 2026 | B5: =SUM(Salary!U43:U54) -> 420244 | C5: =SUM(Salary!P43:P54) -> 17939 | D5: =SUM(Salary!S43:S54) -> 9458 | E5: =SUM(C5,D5) -> 27397 | F5: =SUM(B5,E5) -> 447641 | H5: Hca | I5: Full Time | J5: =SUM(Salary!U48:U69) -> 1000 | K5: =SUM(Salary!P48:P69, Salary!S48:S69) -> 0 | L5: =SUM(J5,K5) -> 1000 | M5: =SUM(Salary!Q48:Q69) -> 0 | O5: =SUM(Salary!T48:T69) -> 0 | P5: =SUM(L5,O5) -> 1000 | R5: 2027-2028 | S5: Apr 2026 - Mar 2027 | T5: 2026-2027 | U5: =SUM(Salary!O46:O57) -> 166422
A6: 2027
A7: 2028
A8: 2029
A9: 2030 | H9: Total | J9: =SUM(J2:J8) -> 1784563.1 | K9: =SUM(K2:K8) -> 144023 | L9: =SUM(L2:L8) -> 1928586.1 | M9: =SUM(M2:M8) -> 6800 | O9: =SUM(O2:O8) -> 17741 | P9: =SUM(P2:P8) -> 2136694.1

Sheet Investments
B3: Scheme | F3: Age ot Entry | G3: Age at Exit | H3: First Installment | I3: Last Installment | J3: Maturity On | K3: Rate of Interest (%) | N3: Tenure | O3: Insurance | Q3: Invested Amount | V3: Expected Corpus
K4: CAGR | L4: XIRR
B5: Person | C5: Relation | D5: Organisation | E5: Scheme Name | L5: Monthly | M5: Yearly | O5: Amount | P5: Upto | Q5: Monthly | R5: Quarterly | S5: Half-Yearly | T5: Yearly | U5: Total | V5: Monthly | W5: Quarterly | X5: Half-Yearly | Y5: Yearly | Z5: On Maturity
B6: Pavan Kalyan Mahanty | C6: Self | D6: Postal Life Insurance | E6: Santosh | F6: 22 | G6: 45 | H6: 45429 | I6: 53448 | J6: 53484 | K6: N.A. | L6: 0.59 | M6: 7.35 | N6: 22 Years | O6: 10,00,000 | P6: Policy ends | Q6: 3550 | R6: =Q6*3 -> 10650 | S6: =Q6*6 -> 21300 | T6: =Q6*12 -> 42600 | U6: 9,37,200 | Z6: 21,44,000
B7: Pavan Kalyan Mahanty | C7: Self | D7: Life Insurance Corporation | E7: Jeevan Anand | F7: 23 | G7: 46 | H7: 45733 | I7: 53768 | J7: 54134 | K7: N.A. | L7: 0.48 | M7: 5.95 | N7: 23 Years | O7: 5,00,000 | P7: Life Long | Q7: =T7/12 -> 2093.5 | R7: =T7/3 -> 8374 | S7: =T7/2 -> 12561 | T7: 25122 | U7: 5,77,806 | Z7: 11,54,000
B8: Tumala Mahanty | C8: Mother | D8: Life Insurance Corporation | E8: Jeevan Anand | F8: 46 | G8: 62 | H8: 42641 | I8: 48301 | J8: 6695898 | K8: N.A. | L8: 0.48 | M8: 2.51 | N8: 16 Years | O8: 1,00,000 | P8: Life Long | Q8: =S8/6 -> 729.33333 | R8: =S8/2 -> 2188 | S8: 4376 | T8: =S8*2 -> 8752 | U8: 1,40,032 | Z8: 1,74,000
B9: Pavan Kalyan Mahanty | C9: Self | D9: Post Office | E9: Time Deposit | F9: 23 | G9: 25 | H9: 46007 | I9: 46737 | J9: 46737 | K9: 7 | L9: 0.58 | M9: 7.185 | N9: 2 Years | O9: N.A. | P9: N.A. | Q9: 3,00,000 | Y9: 21557 | Z9: 3,00,000
B10: Pavan Kalyan Mahanty | C10: Self | D10: Employees' Provident Fund Organisation | E10: Employee Contribution | F10: 21 | G10: 58 | H10: 45139 | I10: 58441 | J10: 58445 | L10: 0.68 | M10: 8.25 | N10: 36 Years | O10: 7,00,000 | P10: Retirement | Q10: 3558 | Z10: =FV(8.25%/12,405,-Q10,-Calculations!K9) -> 10091211

Sheet Employee Details
B3: Employer | C3: EmployeName | D3: Employe ID | E3: Company Location | F3: Role | G3: Employment-Type | H3: Bank Name | I3: Bank Acc.No | J3: Bank IFSC | K3: PF Member ID | L3: Service-History
L4: Start | M4: End | N4: Total | O4: Overall IT Experience
B5: Volante | C5: Pavan Kalyan Mahanty | D5: VSINT057 | E5: Chennai | F5: Software Engineer-Trainee | G5: Internship-Paid | H5: Union | I5: 017510100180659 | J5: UBIN0801755 | K5: N.A. | L5: 44755 | M5: 45138 | N5: =IF(L5<>"",DATEDIF(L5,IF(M5="",TODAY(),M5),"Y")&" Years "&DATEDIF(L5,IF(M5="",TODAY(),M5),"YM")&" Months "&DATEDIF(L5,IF(M5="",TODAY(),M5),"MD")&" Days","") -> 1 Years 0 Months 18 Days | O5: =IF(L5<>"",DATEDIF(L5,IF(M8="",TODAY(),M8),"Y")&" Years "&DATEDIF(L5,IF(M8="",TODAY(),M8),"YM")&" Months "&DATEDIF(L5,IF(M8="",TODAY(),M8),"MD")&" Days","") -> 3 Years 11 Months 2 Days
B6: Volante | C6: Pavan Kalyan Mahanty | D6: VS1550 | E6: Hyderabad | F6: Production Support Engineer II | G6: Full Time | H6: HDFC | I6: 50100629225079 | J6: HDFC0008653 | K6: APHYD21088260000011386 | L6: 45139 | M6: 46015 | N6: =IF(L6<>"",DATEDIF(L6,IF(M6="",TODAY(),M6),"Y")&" Years "&DATEDIF(L6,IF(M6="",TODAY(),M6),"YM")&" Months "&DATEDIF(L6,IF(M6="",TODAY(),M6),"MD")&" Days","") -> 2 Years 4 Months 23 Days
B7: Factset | C7: Pavan Kalyan Mahanty | D7: 48274 | E7: Hyderabad | F7: Senior Specialist II | G7: Full Time | H7: ICICI | I7: 755201503999 | J7: ICIC0007552 | K7: APHYD00618790000080403 | L7: 46020 | M7: 46170 | N7: =IF(L7<>"",DATEDIF(L7,IF(M7="",TODAY(),M7),"Y")&" Years "&DATEDIF(L7,IF(M7="",TODAY(),M7),"YM")&" Months "&DATEDIF(L7,IF(M7="",TODAY(),M7),"MD")&" Days","") -> 0 Years 4 Months 29 Days
B8: Hca HealthCare | C8: Pavan Kalyan Mahanty | D8: QGA2052 | E8: Hyderabad | F8: Site Reliability Engineer II | G8: Full Time | H8: ICICI | I8: 755201503999 | J8: ICIC0007552 | L8: 46174 | M8: =TODAY() -> 46188 | N8: =IF(L8<>"",DATEDIF(L8,IF(M8="",TODAY(),M8),"Y")&" Years "&DATEDIF(L8,IF(M8="",TODAY(),M8),"YM")&" Months "&DATEDIF(L8,IF(M8="",TODAY(),M8),"MD")&" Days","") -> 0 Years 0 Months 14 Days
